Workbook

Sheet Summary
B2: Tumble Wash Laundromat: underwriting summary
B3: 1147 Summit Ave, Jersey City NJ. BizBuySell #2564518. Model as of 2026-10-16. Change assumptions on the Inputs sheet.
B5: Deal
B6: Asking price | C6: =Price -> 450000
B7: Total cash at close (price + closing + working capital) | C7: =TotalInvest -> 480000
B8: Capex scenario selected (1 keep/repair, 2 washers now, 3 full retool, 4 bear) | C8: =CapexScenario -> 1
B9: Equipment capex over the lease (inflated) | C9: =-SUM(Projection!C53:T53) -> 655956.02
B11: Earnings: broker vs. underwritten (Year 1)
C12: Broker | D12: Underwritten | E12: Difference
B13: Revenue | C13: ='Seller Recast'!C9 -> 376200 | D13: ='Seller Recast'!D9 -> 370170 | E13: ='Seller Recast'!E9 -> -6030
B14: Operating expenses | C14: ='Seller Recast'!C28 -> 213780 | D14: ='Seller Recast'!D28 -> 262202.9 | E14: ='Seller Recast'!E28 -> 48422.9
B15: NOI, absentee | C15: ='Seller Recast'!C29 -> 162420 | D15: ='Seller Recast'!D29 -> 107967.1 | E15: ='Seller Recast'!E29 -> -54452.9
B16: Broker's stated NOI / SDE (as listed) | C16: ='Seller Recast'!C31 -> 177720
B17: SDE if Ryan works his hours | D17: =Projection!D49 -> 150191.1
B18: NOI after average equipment reserve | D18: ='Seller Recast'!D40 -> 69381.452
B19: Ask as a multiple of underwritten absentee NOI | D19: =Price/'Seller Recast'!D29 -> 4.1679363
B21: Returns
B22: Pre-tax unlevered IRR, 17 years (absentee) | C22: =Projection!C58 -> 0.17525465
B23: Year-1 cash-on-cash, pre-tax | C23: =Projection!C59 -> 0.22493146
B24: After tax, family level | C24: NPV | D24: IRR | E24: Total tax 1-17 | F24: Year-1 tax
B25: A Ryan owns (gift), single-member LLC | C25: =Structures!C101 -> 388418.1 | D25: =Structures!D101 -> 0.19149462 | E25: =Structures!E101 -> 935027.66 | F25: =Structures!F101 -> 17890.201
B26: B Parents own, passive, no passive income | C26: =Structures!C102 -> 353962.62 | D26: =Structures!D102 -> 0.18300719 | E26: =Structures!E102 -> 589953.97 | F26: =Structures!F102 -> 4437.1989
B27: C Parents own, passive, with passive income | C27: =Structures!C103 -> 371078.76 | D27: =Structures!D103 -> 0.19066626 | E27: =Structures!E103 -> 589953.97 | F27: =Structures!F103 -> 3335.7757
B28: D Ryan owns, AFR loan from parents, S-corp later | C28: =Structures!C104 -> 402532.12 | D28: =Structures!D104 -> 0.19196049 | E28: =Structures!E104 -> 784109.29 | F28: =Structures!F104 -> 9394.8585
B30: Value
B31: Fair value range, low | C31: =Valuation!C29 -> 323901.3
B32: Fair value range, high | C32: =Valuation!D29 -> 377884.85
B33: Max price at pre-tax target return | C33: =Valuation!C19 -> 536926.08
B34: Suggested opening offer | C34: =Valuation!C31 -> 320000
B35: Walk-away price | C35: =Valuation!C32 -> 380000
B37: Scenario snapshot (values pasted by build script; rerun build_model.py after changing inputs)
B38: Case | C38: Yr-1 NOI | D38: Pre-tax IRR | E38: A: NPV | F38: A: IRR | G38: B: NPV | H38: C: NPV | I38: D: NPV
B39: Base: ask $450,000, keep & repair machines | C39: 107967.1 | D39: 0.17525465 | E39: 388418.1 | F39: 0.19149462 | G39: 353962.62 | H39: 371078.76 | I39: 402532.12
B40: Offer $400,000 (90% of ask) | C40: 107967.1 | D40: 0.19350204 | E40: 429483.79 | F40: 0.21052159 | G40: 393738.09 | H40: 410132.2 | I40: 446056.2
B41: Offer $360,000 (80% of ask) | C41: 107967.1 | D41: 0.21094051 | E41: 462336.35 | F41: 0.22887458 | G41: 425645.85 | H41: 441535.16 | I41: 480875.47
B42: Replace washers at close (scenario 2) | C42: 125681.39 | D42: 0.15301022 | E42: 351994.02 | F42: 0.16214813 | G42: 325340.32 | H42: 349952.93 | I42: 378453.28
B43: Full retool at close (scenario 3) | C43: 137141.26 | D43: 0.14531154 | E43: 333913.45 | F43: 0.14938724 | G43: 313843.61 | H43: 345893.61 | I43: 377794.18
B44: Machines fail early (scenario 4) | C44: 107967.1 | D44: 0.15593412 | E44: 363555.84 | F44: 0.16787236 | G44: 340594.45 | H44: 368394.49 | I44: 391693.21
B45: Utilities +20% vs. the P&L | C45: 93711.1 | D45: 0.14628834 | E45: 299019.95 | F45: 0.1710263 | G45: 271285.47 | H45: 292063.53 | I45: 299868.17
B46: Revenue 10% below the P&L | C46: 75543.58 | D46: 0.10378068 | E46: 170160.15 | F46: 0.14140232 | G46: 149259.43 | H46: 177502.7 | I46: 150340.18
...

Sheet Inputs
B2: Inputs: Tumble Wash Laundromat, 1147 Summit Ave, Jersey City NJ
B3: Blue = hardcoded input. Yellow = key assumption / please confirm. Year 1 = first 12 months of ownership (assumed calendar 2027). Edit only column C.
B6: Deal
B7: Purchase price | C7: 450000 | D7: Listing ask (BizBuySell #2564518). Change to test offers.
B8: Closing costs (legal, accounting/QoE, inspection, bulk-sale filing) | C8: 20000 | D8: Estimate. Capitalized with goodwill (15-yr).
B9: Opening working capital (card float, supplies, cash reserve) | C9: 10000 | D9: Estimate. Recovered at exit.
B10: Form 8594 allocation: machines, card system, ATM, vending (Class V) | C10: 60000 | D10: Estimate: ~69 machines at 15 yrs old; support with a distributor appraisal. Seller will want this low (recapture).
B11: Form 8594 allocation: leasehold improvements (curbs, tile, plumbing troughs, venting) | C11: 25000 | D11: Estimate. Qualified improvement property (15-yr, bonus-eligible).
B12: Form 8594 allocation: seller non-compete | C12: 15000 | D12: Estimate. Sec. 197, 15-yr. Negotiate a 5-yr / 3-mile non-compete.
B14: Revenue (Year 1, annual, from the broker P&L unless noted)
B15: Self-serve washer/dryer revenue | C15: 216000 | D15: P&L $18,000/mo; listing $4,150/wk. Verify with 24 months of CCI card-system reports.
B16: Wash-dry-fold pounds per month | C16: 8000 | D16: P&L ~8,000 lb/mo (listing 1,846 lb/wk). Verify in Cents POS.
B17: Wash-dry-fold price per lb (Year 1) | C17: 1.25 | D17: P&L/listing. Local range $1.00-1.25; delivery $1.25-1.49 (research/opex.md).
B18: Wash-dry-fold price per lb after increase | C18: 1.5 | D18: Assumption: raise to $1.50 (CLA survey mode $1.50-1.99).
B19: Year the W&F price increase takes effect | C19: 2 | D19: Assumption.
B20: W&F volume lost when price rises | C20: 0.1 | D20: Assumption.
B21: Drop-off dry cleaning revenue | C21: 6000 | D21: P&L $500/mo.
B22: ATM revenue | C22: 6000 | D22: P&L $500/mo. Seller-owned ATM included. Verify.
B23: Soap vending revenue | C23: 15000 | D23: P&L $1,250/mo. NJ sales tax applies to detergent; confirm whether P&L figure is net of tax.
B24: Snack/soda vending revenue | C24: 7200 | D24: P&L $600/mo.
B25: Game (quarter pusher / arcade) revenue | C25: 6000 | D25: P&L $500/mo. Unverifiable cash; verify.
B26: Share of ancillary (non-laundry) revenue underwritten | C26: 0.85 | D26: Haircut on cash-heavy, unverifiable lines (dry cleaning, ATM, vending, games).
... B30: Self-serve revenue lift from a fully new washer/dryer fleet | C30: 0.05 | D30: Equipment thread base case (5%).
B32: Operating expenses (Year 1)
B33: Rent incl. NNN, CAM and any utilities the lease covers (annual) | C33: 33096 | D33: $2,758/mo per listing; +~3%/yr; ~17 yrs left. Confirm escalation date and that sewer is truly included (P&L says so).
B34: Rent escalation per year | C34: 0.03 | D34: Listing: approx. 3%/yr.
B35: Paid attendant hours per week (absentee model) | C35: 91 | D35: P&L: 91 hrs/wk (store open 112, 21 unattended).
B36: Attendant wage per hour (Year 1) | C36: 17.5 | D36: NJ minimum wage $16.48 from 1/1/2027; local attendants ~$16.50-18 (research/opex.md). P&L uses $16.50.
B37: Wage growth per year | C37: 0.035 | D37: NJ minimum wage is CPI-indexed.
B38: Employer payroll burden (FICA, FUTA, state UI/DI, local payroll tax, workers' comp, sick leave) | C38: 0.16 | D38: research/opex.md: ~16% all-in. P&L shows N/A for payroll tax and WC.
B39: Water and sewer (annual) | C39: 32400 | D39: P&L $2,700/mo. JCMUA rates rise ~5%/yr (2026 $17.82 per 1,000 gal combined).
B40: Gas + electric (annual) | C40: 32400 | D40: P&L $2,700/mo on the 'Gas' line, electric marked 'Inc'. Our read: one combined PSE&G bill. If electric is extra, add it in the next row.
B41: Additional electric not in the broker P&L (annual) | C41: 0 | D41: Set to ~$10-15k if 12 months of PSE&G bills show electric is billed separately.
B42: Utility contingency (unverified bills) | C42: 0.1 | D42: Assumption until 12-24 months of bills are reviewed.
B43: Utility cost inflation per year | C43: 0.04 | D43: PSE&G/JCMUA trend (research/opex.md).
B44: Utility saving with a fully new fleet | C44: 0.2 | D44: Equipment thread: new washers ~25% less water/energy; blended ~20%.
... B61: General expense inflation | C61: 0.03 | D61: Assumption.
B63: Owner time (Ryan)
B64: Hours per week Ryan works in the store (replacing paid attendants) | C64: 40 | D64: Assumption. 500+ hrs/yr (~10/wk) is the material-participation test. Broker: plan 10-15 hrs/wk even 'absentee'.
B66: Owner hand-off and delivery/commercial growth (defaults = off; see Summary scenario table)
...

Sheet Seller Recast
B2: Broker P&L vs. underwritten Year 1 (annual)
B3: Broker column = proforma P&L dated 10-4-26 x 12 (photo IMG_1029), annualized. Underwritten = Projection Year 1.
B5: Line | C5: Broker P&L | D5: Underwritten Yr 1 | E5: Difference | F5: Why
B6: Self-serve | C6: 216000 | D6: =Projection!D11 -> 216000 | E6: =D6-C6 -> 0 | F6: Same; verify with CCI reports.
B7: Wash-dry-fold | C7: 120000 | D7: =Projection!D14 -> 120000 | E7: =D7-C7 -> 0 | F7: Same in Year 1; price increase starts Year 2.
B8: Ancillary (dry cleaning, ATM, vending, games) | C8: 40200 | D8: =Projection!D15 -> 34170 | E8: =D8-C8 -> -6030 | F8: Haircut on unverifiable cash lines.
B9: TOTAL REVENUE | C9: =SUM(C6:C8) -> 376200 | D9: =Projection!D18 -> 370170 | E9: =D9-C9 -> -6030 | F9: Listing says $372k; P&L sums to $376k.
B10: Rent incl. NNN/CAM | C10: 33096 | D10: =Projection!D21 -> 33096 | E10: =D10-C10 -> 0 | F10: From the lease.
B11: Payroll wages | C11: 78084 | D11: =Projection!D22 -> 82810 | E11: =D11-C11 -> 4726 | F11: P&L: 91 hrs x $16.50. 2027 NJ minimum wage is $16.48, so $17.50 to keep staff.
B12: Payroll taxes, workers' comp, sick leave | C12: 0 | D12: =Projection!D23 -> 13249.6 | E12: =D12-C12 -> 13249.6 | F12: P&L shows N/A. Legally required.
B13: Water and sewer | C13: 32400 | D13: =Projection!D24 -> 35640 | E13: =D13-C13 -> 3240 | F13: Plus 10% contingency until bills are seen.
B14: Gas + electric | C14: 32400 | D14: =Projection!D25 -> 35640 | E14: =D14-C14 -> 3240 | F14: Electric marked 'Inc'; confirm with bills.
B15: Repairs & maintenance | C15: 5400 | D15: =Projection!D26 -> 12000 | E15: =D15-C15 -> 6600 | F15: 15-yr fleet; seller likely does own repairs unpaid.
B16: Insurance | C16: 2880 | D16: =Projection!D27 -> 7500 | E16: =D16-C16 -> 4620 | F16: $240/mo is too low for property + GL + equipment breakdown.
B17: Card processing | C17: 4800 | D17: =Projection!D28 -> 4804.8 | E17: =D17-C17 -> 4.8
B18: POS system & cards | C18: 6600 | D18: =Projection!D29 -> 6600 | E18: =D18-C18 -> 0
B19: W&F supplies | C19: 3600 | D19: =Projection!D30 -> 3600 | E19: =D19-C19 -> 0
B20: Vending COGS + dry cleaning cost | C20: 10500 | D20: =Projection!D31 -> 8965.8 | E20: =D20-C20 -> -1534.2
B21: Phone, alarm, trash | C21: 2220 | D21: =Projection!D32 -> 2595 | E21: =D21-C21 -> 375 | F21: Underwritten adds the $375/yr fire alarm noted on the P&L.
B22: Misc. supplies | C22: 1800 | D22: =Projection!D33 -> 1800 | E22: =D22-C22 -> 0
B23: Accounting, tax & legal | C23: 0 | D23: =Projection!D34 -> 5000 | E23: =D23-C23 -> 5000 | F23: Not in P&L.
B24: Licenses & fees | C24: 0 | D24: =Projection!D35 -> 1000 | E24: =D24-C24 -> 1000 | F24: Not in P&L.
B25: Payroll service | C25: 0 | D25: =Projection!D36 -> 1200 | E25: =D25-C25 -> 1200 | F25: Not in P&L.
B26: Marketing | C26: 0 | D26: =Projection!D37 -> 3000 | E26: =D26-C26 -> 3000 | F26: Not in P&L.
B27: Contingency | C27: 0 | D27: =Projection!D42 -> 3701.7 | E27: =D27-C27 -> 3701.7 | F27: 1% of revenue.
B28: TOTAL EXPENSES | C28: =SUM(C10:C27) -> 213780 | D28: =Projection!D43 -> 262202.9 | E28: =D28-C28 -> 48422.9 | F28: Broker's lines add to $17,815/mo; the P&L's TOTAL says $16,540.
B29: NET OPERATING INCOME (absentee) | C29: =C9-C28 -> 162420 | D29: =Projection!D45 -> 107967.1 | E29: =D29-C29 -> -54452.9 | F29: Broker's lines, added correctly: $162,420, not $177,720.
B31: Broker's stated NOI / SDE (as listed) | C31: 177720 | F31: P&L TOTAL omits vending COGS, dry cleaning cost and card fees ($1,275/mo). Lines added correctly give $162,420.
B32: Note: underwritten Year 1 uses the selected capex scenario; under scenarios 2/3 new machines lift revenue and cut utilities/repairs.
B34: Implied price multiples
B35: Ask / broker's stated NOI | D35: =Price/C31 -> 2.5320729
B36: Ask / underwritten NOI (absentee) | D36: =Price/D29 -> 4.1679363
B37: Ask / underwritten SDE (Ryan works his hours) | D37: =Price/Projection!D49 -> 2.9961829
B38: Ask / underwritten revenue | D38: =Price/D9 -> 1.2156577
B40: Underwritten NOI after equipment reserve (avg. annual capex) | D40: =D29-Projection!C60 -> 69381.452

Sheet Valuation
B2: Valuation: what is this store worth?
B3: Three approaches. Market multiples come from the Comps sheet and research/comps.md.
B5: Earnings bases (Year 1, underwritten)
B6: NOI, absentee (all hours paid) | C6: ='Seller Recast'!D29 -> 107967.1
B7: SDE, Ryan works his hours | C7: =Projection!D49 -> 150191.1
B8: NOI after equipment reserve | C8: ='Seller Recast'!D40 -> 69381.452
B9: Broker's stated NOI | C9: ='Seller Recast'!C31 -> 177720
B11: 1. Market approach: earnings x comparable multiples
B12: Multiple | C12: x | D12: x NOI | E12: x SDE | F12: x NOI after reserve
B13: Low (old fleet, NYC metro sold median less) | C13: 2.5 | D13: =$C13*$C$6 -> 269917.75 | E13: =$C13*$C$7 -> 375477.75 | F13: =$C13*$C$8 -> 173453.63 | G13: Sources: underwriting/research/comps.md (BizBuySell Insight 855 deals; 28 NYC-metro listings; Laundromat Resource rules of thumb)
B14: Sold-listing median, NYC metro | C14: 3.3 | D14: =$C14*$C$6 -> 356291.43 | E14: =$C14*$C$7 -> 495630.63 | F14: =$C14*$C$8 -> 228958.79
B15: National closed-deal median (BizBuySell 2021-25) | C15: 3.5 | D15: =$C15*$C$6 -> 377884.85 | E15: =$C15*$C$7 -> 525668.85 | F15: =$C15*$C$8 -> 242835.08
B16: Rule of thumb, 15+ yr lease, low rent | C16: 4 | D16: =$C16*$C$6 -> 431868.4 | E16: =$C16*$C$7 -> 600764.4 | F16: =$C16*$C$8 -> 277525.81
B18: 2. Income approach: price that still earns the target return
B19: Max price at pre-tax target return (absentee cash flows, selected capex) | C19: =(NPV(PreTaxTarget,Projection!D55:T55)+Projection!C53-ClosingCosts-WorkingCap) -> 536926.08 | G19: PV of Years 1-17 at the target, less Year-0 capex, closing costs and working capital.
B20: Max price at after-tax discount rate: structure A | C20: =Price+Structures!C101 -> 838418.1 | G20: Ask + NPV (approx.; taxes held at the current price's allocation).
B21: Max price at after-tax discount rate: structure B | C21: =Price+Structures!C102 -> 803962.62 | G21: Ask + NPV (approx.; taxes held at the current price's allocation).
B22: Max price at after-tax discount rate: structure C | C22: =Price+Structures!C103 -> 821078.76 | G22: Ask + NPV (approx.; taxes held at the current price's allocation).
B23: Max price at after-tax discount rate: structure D | C23: =Price+Structures!C104 -> 852532.12 | G23: Ask + NPV (approx.; taxes held at the current price's allocation).
B25: 3. Asset-light floor
B26: Used-equipment value + improvements (liquidation-ish floor) | C26: =AllocEquip+AllocLHI -> 85000
B28: Conclusion
B29: Fair value range: 3.0x (low) to 3.5x (high) underwritten absentee NOI | C29: =3*C6 -> 323901.3 | D29: =3.5*C6 -> 377884.85
B30: Asking price | C30: =Price -> 450000
B31: Suggested opening offer (3.0x absentee NOI, rounded) | C31: =ROUND(3*C6,-4) -> 320000
B32: Walk-away price (3.5x absentee NOI, rounded) | C32: =ROUND(3.5*C6,-4) -> 380000

Sheet Projection
B2: 17-year projection (pre-tax, absentee basis: every staffed hour is paid)
B3: Year 0 = closing. Taxes by ownership structure are on the Structures sheet.
B5: Year | C5: 0 | D5: 1 | E5: 2 | F5: 3 | G5: 4 | H5: 5 | I5: 6 | J5: 7 | K5: 8 | L5: 9 | M5: 10 | N5: 11 | O5: 12 | P5: 13 | Q5: 14 | R5: 15 | S5: 16 | T5: 17 | U5: Total 1-17
B6: Calendar year (assumed) | C6: 2026 | D6: 2027 | E6: 2028 | F6: 2029 | G6: 2030 | H6: 2031 | I6: 2032 | J6: 2033 | K6: 2034 | L6: 2035 | M6: 2036 | N6: 2037 | O6: 2038 | P6: 2039 | Q6: 2040 | R6: 2041 | S6: 2042 | T6: 2043
B7: Share of fleet new | C7: =Depreciation!C13 -> 0 | D7: =Depreciation!D13 -> 0 | E7: =Depreciation!E13 -> 0 | F7: =Depreciation!F13 -> 0 | G7: =Depreciation!G13 -> 0 | H7: =Depreciation!H13 -> 0.63914655 | I7: =Depreciation!I13 -> 0.63914655 | J7: =Depreciation!J13 -> 0.63914655 | ... T7: =Depreciation!T13 -> 1
B8: Years of growth (y-1) | D8: =D5-1 -> 0 | E8: =E5-1 -> 1 | F8: =F5-1 -> 2 | G8: =G5-1 -> 3 | H8: =H5-1 -> 4 | I8: =I5-1 -> 5 | J8: =J5-1 -> 6 | K8: =K5-1 -> 7 | ... T8: =T5-1 -> 16
B10: Revenue
B11: Self-serve wash & dry | D11: =SelfServe*(1+SSGrowth)^D$8*(1+RetoolLift*D$7) -> 216000 | E11: =SelfServe*(1+SSGrowth)^E$8*(1+RetoolLift*E$7) -> 222480 | F11: =SelfServe*(1+SSGrowth)^F$8*(1+RetoolLift*F$7) -> 229154.4 | G11: =SelfServe*(1+SSGrowth)^G$8*(1+RetoolLift*G$7) -> 236029.03 | H11: =SelfServe*(1+SSGrowth)^H$8*(1+RetoolLift*H$7) -> 250879.05 | I11: =SelfServe*(1+SSGrowth)^I$8*(1+RetoolLift*I$7) -> 258405.42 | J11: =SelfServe*(1+SSGrowth)^J$8*(1+RetoolLift*J$7) -> 266157.58 | K11: =SelfServe*(1+SSGrowth)^K$8*(1+RetoolLift*K$7) -> 274142.31 | ... T11: =SelfServe*(1+SSGrowth)^T$8*(1+RetoolLift*T$7) -> 363947.42 | U11: =SUM(D11:T11) -> 4856734.7
B12: W&F pounds | D12: =WFLbsMonth*12*IF(D$5>=WFPriceYear,1-WFVolLoss,1) -> 96000 | E12: =WFLbsMonth*12*IF(E$5>=WFPriceYear,1-WFVolLoss,1) -> 86400 | F12: =WFLbsMonth*12*IF(F$5>=WFPriceYear,1-WFVolLoss,1) -> 86400 | G12: =WFLbsMonth*12*IF(G$5>=WFPriceYear,1-WFVolLoss,1) -> 86400 | H12: =WFLbsMonth*12*IF(H$5>=WFPriceYear,1-WFVolLoss,1) -> 86400 | I12: =WFLbsMonth*12*IF(I$5>=WFPriceYear,1-WFVolLoss,1) -> 86400 | J12: =WFLbsMonth*12*IF(J$5>=WFPriceYear,1-WFVolLoss,1) -> 86400 | K12: =WFLbsMonth*12*IF(K$5>=WFPriceYear,1-WFVolLoss,1) -> 86400 | ... T12: =WFLbsMonth*12*IF(T$5>=WFPriceYear,1-WFVolLoss,1) -> 86400 | U12: =SUM(D12:T12) -> 1478400
B13: W&F price per lb | D13: =IF(D$5>=WFPriceYear,WFPriceNew,WFPrice)*(1+WFGrowth)^MAX(0,D$5-WFPriceYear) -> 1.25 | E13: =IF(E$5>=WFPriceYear,WFPriceNew,WFPrice)*(1+WFGrowth)^MAX(0,E$5-WFPriceYear) -> 1.5 | F13: =IF(F$5>=WFPriceYear,WFPriceNew,WFPrice)*(1+WFGrowth)^MAX(0,F$5-WFPriceYear) -> 1.545 | G13: =IF(G$5>=WFPriceYear,WFPriceNew,WFPrice)*(1+WFGrowth)^MAX(0,G$5-WFPriceYear) -> 1.59135 | H13: =IF(H$5>=WFPriceYear,WFPriceNew,WFPrice)*(1+WFGrowth)^MAX(0,H$5-WFPriceYear) -> 1.6390905 | I13: =IF(I$5>=WFPriceYear,WFPriceNew,WFPrice)*(1+WFGrowth)^MAX(0,I$5-WFPriceYear) -> 1.6882632 | J13: =IF(J$5>=WFPriceYear,WFPriceNew,WFPrice)*(1+WFGrowth)^MAX(0,J$5-WFPriceYear) -> 1.7389111 | K13: =IF(K$5>=WFPriceYear,WFPriceNew,WFPrice)*(1+WFGrowth)^MAX(0,K$5-WFPriceYear) -> 1.7910784 | ... T13: =IF(T$5>=WFPriceYear,WFPriceNew,WFPrice)*(1+WFGrowth)^MAX(0,T$5-WFPriceYear) -> 2.3369511
B14: Wash-dry-fold (incl. pickup & delivery) | D14: =D12*D13 -> 120000 | E14: =E12*E13 -> 129600 | F14: =F12*F13 -> 133488 | G14: =G12*G13 -> 137492.64 | H14: =H12*H13 -> 141617.42 | I14: =I12*I13 -> 145865.94 | J14: =J12*J13 -> 150241.92 | K14: =K12*K13 -> 154749.18 | ... T14: =T12*T13 -> 201912.58 | U14: =SUM(D14:T14) -> 2732331.8
B15: Ancillary (dry cleaning, ATM, vending, games), after haircut | D15: =AncYr1*(1+AncGrowth)^D$8 -> 34170 | E15: =AncYr1*(1+AncGrowth)^E$8 -> 34853.4 | F15: =AncYr1*(1+AncGrowth)^F$8 -> 35550.468 | G15: =AncYr1*(1+AncGrowth)^G$8 -> 36261.477 | H15: =AncYr1*(1+AncGrowth)^H$8 -> 36986.707 | I15: =AncYr1*(1+AncGrowth)^I$8 -> 37726.441 | J15: =AncYr1*(1+AncGrowth)^J$8 -> 38480.97 | K15: =AncYr1*(1+AncGrowth)^K$8 -> 39250.589 | ... T15: =AncYr1*(1+AncGrowth)^T$8 -> 46908.088 | U15: =SUM(D15:T15) -> 683812.46
B16: Delivery/commercial pounds | D16: =IF(D$5<DelivStart,0,IF(D$5=DelivStart,DelivLbsRamp,DelivLbsFull))*12 -> 0 | E16: =IF(E$5<DelivStart,0,IF(E$5=DelivStart,DelivLbsRamp,DelivLbsFull))*12 -> 0 | F16: =IF(F$5<DelivStart,0,IF(F$5=DelivStart,DelivLbsRamp,DelivLbsFull))*12 -> 0 | G16: =IF(G$5<DelivStart,0,IF(G$5=DelivStart,DelivLbsRamp,DelivLbsFull))*12 -> 0 | H16: =IF(H$5<DelivStart,0,IF(H$5=DelivStart,DelivLbsRamp,DelivLbsFull))*12 -> 0 | I16: =IF(I$5<DelivStart,0,IF(I$5=DelivStart,DelivLbsRamp,DelivLbsFull))*12 -> 0 | J16: =IF(J$5<DelivStart,0,IF(J$5=DelivStart,DelivLbsRamp,DelivLbsFull))*12 -> 0 | K16: =IF(K$5<DelivStart,0,IF(K$5=DelivStart,DelivLbsRamp,DelivLbsFull))*12 -> 0 | ... T16: =IF(T$5<DelivStart,0,IF(T$5=DelivStart,DelivLbsRamp,DelivLbsFull))*12 -> 0 | U16: =SUM(D16:T16) -> 0
B17: Pickup/delivery + commercial wash-dry-fold | D17: =D16*DelivPrice*(1+WFGrowth)^MAX(0,D$5-DelivStart) -> 0 | E17: =E16*DelivPrice*(1+WFGrowth)^MAX(0,E$5-DelivStart) -> 0 | F17: =F16*DelivPrice*(1+WFGrowth)^MAX(0,F$5-DelivStart) -> 0 | G17: =G16*DelivPrice*(1+WFGrowth)^MAX(0,G$5-DelivStart) -> 0 | H17: =H16*DelivPrice*(1+WFGrowth)^MAX(0,H$5-DelivStart) -> 0 | I17: =I16*DelivPrice*(1+WFGrowth)^MAX(0,I$5-DelivStart) -> 0 | J17: =J16*DelivPrice*(1+WFGrowth)^MAX(0,J$5-DelivStart) -> 0 | K17: =K16*DelivPrice*(1+WFGrowth)^MAX(0,K$5-DelivStart) -> 0 | ... T17: =T16*DelivPrice*(1+WFGrowth)^MAX(0,T$5-DelivStart) -> 0 | U17: =SUM(D17:T17) -> 0
B18: Total revenue | D18: =D11+D14+D15+D17 -> 370170 | E18: =E11+E14+E15+E17 -> 386933.4 | F18: =F11+F14+F15+F17 -> 398192.87 | G18: =G11+G14+G15+G17 -> 409783.15 | H18: =H11+H14+H15+H17 -> 429483.17 | I18: =I11+I14+I15+I17 -> 441997.8 | J18: =J11+J14+J15+J17 -> 454880.47 | K18: =K11+K14+K15+K17 -> 468142.07 | ... T18: =T11+T14+T15+T17 -> 612768.09 | U18: =SUM(D18:T18) -> 8272879
B20: Operating expenses
B21: Rent (incl. NNN, CAM, sewer) | D21: =RentYr1*(1+RentEsc)^D$8 -> 33096 | E21: =RentYr1*(1+RentEsc)^E$8 -> 34088.88 | F21: =RentYr1*(1+RentEsc)^F$8 -> 35111.546 | G21: =RentYr1*(1+RentEsc)^G$8 -> 36164.893 | H21: =RentYr1*(1+RentEsc)^H$8 -> 37249.84 | I21: =RentYr1*(1+RentEsc)^I$8 -> 38367.335 | J21: =RentYr1*(1+RentEsc)^J$8 -> 39518.355 | K21: =RentYr1*(1+RentEsc)^K$8 -> 40703.905 | ... T21: =RentYr1*(1+RentEsc)^T$8 -> 53109.364 | U21: =SUM(D21:T21) -> 720221.51
B22: Attendant wages | D22: =PaidHours*52*Wage*(1+WageGrowth)^D$8 -> 82810 | E22: =PaidHours*52*Wage*(1+WageGrowth)^E$8 -> 85708.35 | F22: =PaidHours*52*Wage*(1+WageGrowth)^F$8 -> 88708.142 | G22: =PaidHours*52*Wage*(1+WageGrowth)^G$8 -> 91812.927 | H22: =PaidHours*52*Wage*(1+WageGrowth)^H$8 -> 95026.38 | I22: =PaidHours*52*Wage*(1+WageGrowth)^I$8 -> 98352.303 | J22: =PaidHours*52*Wage*(1+WageGrowth)^J$8 -> 101794.63 | K22: =PaidHours*52*Wage*(1+WageGrowth)^K$8 -> 105357.45 | ... T22: =PaidHours*52*Wage*(1+WageGrowth)^T$8 -> 143591.38 | U22: =SUM(D22:T22) -> 1880202.4
B23: Employer payroll taxes, workers' comp, sick leave | D23: =D22*Burden -> 13249.6 | E23: =E22*Burden -> 13713.336 | F23: =F22*Burden -> 14193.303 | G23: =G22*Burden -> 14690.068 | H23: =H22*Burden -> 15204.221 | I23: =I22*Burden -> 15736.368 | J23: =J22*Burden -> 16287.141 | K23: =K22*Burden -> 16857.191 | ... T23: =T22*Burden -> 22974.621 | U23: =SUM(D23:T23) -> 300832.38
B24: Water | D24: =WaterYr1*(1+UtilCont)*(1+UtilInfl)^D$8*(1-UtilSave*D$7) -> 35640 | E24: =WaterYr1*(1+UtilCont)*(1+UtilInfl)^E$8*(1-UtilSave*E$7) -> 37065.6 | F24: =WaterYr1*(1+UtilCont)*(1+UtilInfl)^F$8*(1-UtilSave*F$7) -> 38548.224 | G24: =WaterYr1*(1+UtilCont)*(1+UtilInfl)^G$8*(1-UtilSave*G$7) -> 40090.153 | H24: =WaterYr1*(1+UtilCont)*(1+UtilInfl)^H$8*(1-UtilSave*H$7) -> 36364.075 | I24: =WaterYr1*(1+UtilCont)*(1+UtilInfl)^I$8*(1-UtilSave*I$7) -> 37818.638 | J24: =WaterYr1*(1+UtilCont)*(1+UtilInfl)^J$8*(1-UtilSave*J$7) -> 39331.383 | K24: =WaterYr1*(1+UtilCont)*(1+UtilInfl)^K$8*(1-UtilSave*K$7) -> 40904.638 | ... T24: =WaterYr1*(1+UtilCont)*(1+UtilInfl)^T$8*(1-UtilSave*T$7) -> 53402.441 | U24: =SUM(D24:T24) -> 729698.77
B25: Gas + electric | D25: =(GasElecYr1+ElecExtra)*(1+UtilCont)*(1+UtilInfl)^D$8*(1-UtilSave*D$7) -> 35640 | E25: =(GasElecYr1+ElecExtra)*(1+UtilCont)*(1+UtilInfl)^E$8*(1-UtilSave*E$7) -> 37065.6 | F25: =(GasElecYr1+ElecExtra)*(1+UtilCont)*(1+UtilInfl)^F$8*(1-UtilSave*F$7) -> 38548.224 | G25: =(GasElecYr1+ElecExtra)*(1+UtilCont)*(1+UtilInfl)^G$8*(1-UtilSave*G$7) -> 40090.153 | H25: =(GasElecYr1+ElecExtra)*(1+UtilCont)*(1+UtilInfl)^H$8*(1-UtilSave*H$7) -> 36364.075 | I25: =(GasElecYr1+ElecExtra)*(1+UtilCont)*(1+UtilInfl)^I$8*(1-UtilSave*I$7) -> 37818.638 | J25: =(GasElecYr1+ElecExtra)*(1+UtilCont)*(1+UtilInfl)^J$8*(1-UtilSave*J$7) -> 39331.383 | K25: =(GasElecYr1+ElecExtra)*(1+UtilCont)*(1+UtilInfl)^K$8*(1-UtilSave*K$7) -> 40904.638 | ... T25: =(GasElecYr1+ElecExtra)*(1+UtilCont)*(1+UtilInfl)^T$8*(1-UtilSave*T$7) -> 53402.441 | U25: =SUM(D25:T25) -> 729698.77
B26: Repairs & maintenance | D26: =RepairsYr1*(1+RepairsAging)^D$8*(1-D$7)+D18*RepairsNewPct*D$7 -> 12000 | E26: =RepairsYr1*(1+RepairsAging)^E$8*(1-E$7)+E18*RepairsNewPct*E$7 -> 12960 | F26: =RepairsYr1*(1+RepairsAging)^F$8*(1-F$7)+F18*RepairsNewPct*F$7 -> 13996.8 | G26: =RepairsYr1*(1+RepairsAging)^G$8*(1-G$7)+G18*RepairsNewPct*G$7 -> 15116.544 | H26: =RepairsYr1*(1+RepairsAging)^H$8*(1-H$7)+H18*RepairsNewPct*H$7 -> 11381.299 | I26: =RepairsYr1*(1+RepairsAging)^I$8*(1-I$7)+I18*RepairsNewPct*I$7 -> 12012.573 | J26: =RepairsYr1*(1+RepairsAging)^J$8*(1-J$7)+J18*RepairsNewPct*J$7 -> 12686.255 | K26: =RepairsYr1*(1+RepairsAging)^K$8*(1-K$7)+K18*RepairsNewPct*K$7 -> 13405.501 | ... T26: =RepairsYr1*(1+RepairsAging)^T$8*(1-T$7)+T18*RepairsNewPct*T$7 -> 12255.362 | U26: =SUM(D26:T26) -> 217106.03
B27: Insurance | D27: =Insurance*(1+ExpInfl)^D$8 -> 7500 | E27: =Insurance*(1+ExpInfl)^E$8 -> 7725 | F27: =Insurance*(1+ExpInfl)^F$8 -> 7956.75 | G27: =Insurance*(1+ExpInfl)^G$8 -> 8195.4525 | H27: =Insurance*(1+ExpInfl)^H$8 -> 8441.3161 | I27: =Insurance*(1+ExpInfl)^I$8 -> 8694.5556 | J27: =Insurance*(1+ExpInfl)^J$8 -> 8955.3922 | K27: =Insurance*(1+ExpInfl)^K$8 -> 9224.054 | ... T27: =Insurance*(1+ExpInfl)^T$8 -> 12035.298 | U27: =SUM(D27:T27) -> 163211.91
B28: Card processing | D28: =(D11+D14)*CardFeePct -> 4804.8 | E28: =(E11+E14)*CardFeePct -> 5034.744 | F28: =(F11+F14)*CardFeePct -> 5185.7863 | G28: =(G11+G14)*CardFeePct -> 5341.3599 | H28: =(H11+H14)*CardFeePct -> 5612.6994 | I28: =(I11+I14)*CardFeePct -> 5781.0804 | J28: =(J11+J14)*CardFeePct -> 5954.5128 | K28: =(K11+K14)*CardFeePct -> 6133.1482 | ... T28: =(T11+T14)*CardFeePct -> 8091.798 | U28: =SUM(D28:T28) -> 108523.65
B29: POS system & cards | D29: =POS*(1+ExpInfl)^D$8 -> 6600 | E29: =POS*(1+ExpInfl)^E$8 -> 6798 | F29: =POS*(1+ExpInfl)^F$8 -> 7001.94 | G29: =POS*(1+ExpInfl)^G$8 -> 7211.9982 | H29: =POS*(1+ExpInfl)^H$8 -> 7428.3581 | I29: =POS*(1+ExpInfl)^I$8 -> 7651.2089 | J29: =POS*(1+ExpInfl)^J$8 -> 7880.7452 | K29: =POS*(1+ExpInfl)^K$8 -> 8117.1675 | ... T29: =POS*(1+ExpInfl)^T$8 -> 10591.062 | U29: =SUM(D29:T29) -> 143626.48
B30: W&F supplies | D30: =D12*WFSupplyLb*(1+ExpInfl)^D$8 -> 3600 | E30: =E12*WFSupplyLb*(1+ExpInfl)^E$8 -> 3337.2 | F30: =F12*WFSupplyLb*(1+ExpInfl)^F$8 -> 3437.316 | G30: =G12*WFSupplyLb*(1+ExpInfl)^G$8 -> 3540.4355 | H30: =H12*WFSupplyLb*(1+ExpInfl)^H$8 -> 3646.6485 | I30: =I12*WFSupplyLb*(1+ExpInfl)^I$8 -> 3756.048 | J30: =J12*WFSupplyLb*(1+ExpInfl)^J$8 -> 3868.7294 | K30: =K12*WFSupplyLb*(1+ExpInfl)^K$8 -> 3984.7913 | ... T30: =T12*WFSupplyLb*(1+ExpInfl)^T$8 -> 5199.2489 | U30: =SUM(D30:T30) -> 70867.544
B31: Vending COGS + dry cleaning cost | D31: =D15*((SoapVend+SnackVend)*VendCOGS+DryClean*DCCost)/(DryClean+ATM+SoapVend+SnackVend+GameVend) -> 8965.8 | E31: =E15*((SoapVend+SnackVend)*VendCOGS+DryClean*DCCost)/(DryClean+ATM+SoapVend+SnackVend+GameVend) -> 9145.116 | F31: =F15*((SoapVend+SnackVend)*VendCOGS+DryClean*DCCost)/(DryClean+ATM+SoapVend+SnackVend+GameVend) -> 9328.0183 | G31: =G15*((SoapVend+SnackVend)*VendCOGS+DryClean*DCCost)/(DryClean+ATM+SoapVend+SnackVend+GameVend) -> 9514.5787 | H31: =H15*((SoapVend+SnackVend)*VendCOGS+DryClean*DCCost)/(DryClean+ATM+SoapVend+SnackVend+GameVend) -> 9704.8703 | I31: =I15*((SoapVend+SnackVend)*VendCOGS+DryClean*DCCost)/(DryClean+ATM+SoapVend+SnackVend+GameVend) -> 9898.9677 | J31: =J15*((SoapVend+SnackVend)*VendCOGS+DryClean*DCCost)/(DryClean+ATM+SoapVend+SnackVend+GameVend) -> 10096.947 | K31: =K15*((SoapVend+SnackVend)*VendCOGS+DryClean*DCCost)/(DryClean+ATM+SoapVend+SnackVend+GameVend) -> 10298.886 | ... T31: =T15*((SoapVend+SnackVend)*VendCOGS+DryClean*DCCost)/(DryClean+ATM+SoapVend+SnackVend+GameVend) -> 12308.122 | U31: =SUM(D31:T31) -> 179424.23
B32: Phone, alarm, trash | D32: =TeleAlarmTrash*(1+ExpInfl)^D$8 -> 2595 | E32: =TeleAlarmTrash*(1+ExpInfl)^E$8 -> 2672.85 | F32: =TeleAlarmTrash*(1+ExpInfl)^F$8 -> 2753.0355 | G32: =TeleAlarmTrash*(1+ExpInfl)^G$8 -> 2835.6266 | H32: =TeleAlarmTrash*(1+ExpInfl)^H$8 -> 2920.6954 | I32: =TeleAlarmTrash*(1+ExpInfl)^I$8 -> 3008.3162 | J32: =TeleAlarmTrash*(1+ExpInfl)^J$8 -> 3098.5657 | K32: =TeleAlarmTrash*(1+ExpInfl)^K$8 -> 3191.5227 | ... T32: =TeleAlarmTrash*(1+ExpInfl)^T$8 -> 4164.2132 | U32: =SUM(D32:T32) -> 56471.32
B33: Misc. supplies | D33: =MiscSupplies*(1+ExpInfl)^D$8 -> 1800 | E33: =MiscSupplies*(1+ExpInfl)^E$8 -> 1854 | F33: =MiscSupplies*(1+ExpInfl)^F$8 -> 1909.62 | G33: =MiscSupplies*(1+ExpInfl)^G$8 -> 1966.9086 | H33: =MiscSupplies*(1+ExpInfl)^H$8 -> 2025.9159 | I33: =MiscSupplies*(1+ExpInfl)^I$8 -> 2086.6933 | J33: =MiscSupplies*(1+ExpInfl)^J$8 -> 2149.2941 | K33: =MiscSupplies*(1+ExpInfl)^K$8 -> 2213.773 | ... T33: =MiscSupplies*(1+ExpInfl)^T$8 -> 2888.4716 | U33: =SUM(D33:T33) -> 39170.858
B34: Accounting, tax & legal | D34: =ProFees*(1+ExpInfl)^D$8 -> 5000 | E34: =ProFees*(1+ExpInfl)^E$8 -> 5150 | F34: =ProFees*(1+ExpInfl)^F$8 -> 5304.5 | G34: =ProFees*(1+ExpInfl)^G$8 -> 5463.635 | H34: =ProFees*(1+ExpInfl)^H$8 -> 5627.5441 | I34: =ProFees*(1+ExpInfl)^I$8 -> 5796.3704 | J34: =ProFees*(1+ExpInfl)^J$8 -> 5970.2615 | K34: =ProFees*(1+ExpInfl)^K$8 -> 6149.3693 | ... T34: =ProFees*(1+ExpInfl)^T$8 -> 8023.5322 | U34: =SUM(D34:T34) -> 108807.94
B35: Licenses & fees | D35: =Licenses*(1+ExpInfl)^D$8 -> 1000 | E35: =Licenses*(1+ExpInfl)^E$8 -> 1030 | F35: =Licenses*(1+ExpInfl)^F$8 -> 1060.9 | G35: =Licenses*(1+ExpInfl)^G$8 -> 1092.727 | H35: =Licenses*(1+ExpInfl)^H$8 -> 1125.5088 | I35: =Licenses*(1+ExpInfl)^I$8 -> 1159.2741 | J35: =Licenses*(1+ExpInfl)^J$8 -> 1194.0523 | K35: =Licenses*(1+ExpInfl)^K$8 -> 1229.8739 | ... T35: =Licenses*(1+ExpInfl)^T$8 -> 1604.7064 | U35: =SUM(D35:T35) -> 21761.588
B36: Payroll service | D36: =PayrollSvc*(1+ExpInfl)^D$8 -> 1200 | E36: =PayrollSvc*(1+ExpInfl)^E$8 -> 1236 | F36: =PayrollSvc*(1+ExpInfl)^F$8 -> 1273.08 | G36: =PayrollSvc*(1+ExpInfl)^G$8 -> 1311.2724 | H36: =PayrollSvc*(1+ExpInfl)^H$8 -> 1350.6106 | I36: =PayrollSvc*(1+ExpInfl)^I$8 -> 1391.1289 | J36: =PayrollSvc*(1+ExpInfl)^J$8 -> 1432.8628 | K36: =PayrollSvc*(1+ExpInfl)^K$8 -> 1475.8486 | ... T36: =PayrollSvc*(1+ExpInfl)^T$8 -> 1925.6477 | U36: =SUM(D36:T36) -> 26113.905
B37: Marketing | D37: =Marketing*(1+ExpInfl)^D$8 -> 3000 | E37: =Marketing*(1+ExpInfl)^E$8 -> 3090 | F37: =Marketing*(1+ExpInfl)^F$8 -> 3182.7 | G37: =Marketing*(1+ExpInfl)^G$8 -> 3278.181 | H37: =Marketing*(1+ExpInfl)^H$8 -> 3376.5264 | I37: =Marketing*(1+ExpInfl)^I$8 -> 3477.8222 | J37: =Marketing*(1+ExpInfl)^J$8 -> 3582.1569 | K37: =Marketing*(1+ExpInfl)^K$8 -> 3689.6216 | ... T37: =Marketing*(1+ExpInfl)^T$8 -> 4814.1193 | U37: =SUM(D37:T37) -> 65284.763
B38: Day-manager pay premium (after hand-off) | D38: =IF(D$5>=HandoffYear,MgrHours*52*MgrPremium*(1+WageGrowth)^D$8*(1+Burden),0) -> 0 | E38: =IF(E$5>=HandoffYear,MgrHours*52*MgrPremium*(1+WageGrowth)^E$8*(1+Burden),0) -> 0 | F38: =IF(F$5>=HandoffYear,MgrHours*52*MgrPremium*(1+WageGrowth)^F$8*(1+Burden),0) -> 0 | G38: =IF(G$5>=HandoffYear,MgrHours*52*MgrPremium*(1+WageGrowth)^G$8*(1+Burden),0) -> 0 | H38: =IF(H$5>=HandoffYear,MgrHours*52*MgrPremium*(1+WageGrowth)^H$8*(1+Burden),0) -> 0 | I38: =IF(I$5>=HandoffYear,MgrHours*52*MgrPremium*(1+WageGrowth)^I$8*(1+Burden),0) -> 0 | J38: =IF(J$5>=HandoffYear,MgrHours*52*MgrPremium*(1+WageGrowth)^J$8*(1+Burden),0) -> 0 | K38: =IF(K$5>=HandoffYear,MgrHours*52*MgrPremium*(1+WageGrowth)^K$8*(1+Burden),0) -> 0 | ... T38: =IF(T$5>=HandoffYear,MgrHours*52*MgrPremium*(1+WageGrowth)^T$8*(1+Burden),0) -> 0 | U38: =SUM(D38:T38) -> 0
B39: Delivery program: processing labor | D39: =D16/LbsPerHour*DelivLaborShare*Wage*(1+WageGrowth)^D$8*(1+Burden) -> 0 | E39: =E16/LbsPerHour*DelivLaborShare*Wage*(1+WageGrowth)^E$8*(1+Burden) -> 0 | F39: =F16/LbsPerHour*DelivLaborShare*Wage*(1+WageGrowth)^F$8*(1+Burden) -> 0 | G39: =G16/LbsPerHour*DelivLaborShare*Wage*(1+WageGrowth)^G$8*(1+Burden) -> 0 | H39: =H16/LbsPerHour*DelivLaborShare*Wage*(1+WageGrowth)^H$8*(1+Burden) -> 0 | I39: =I16/LbsPerHour*DelivLaborShare*Wage*(1+WageGrowth)^I$8*(1+Burden) -> 0 | J39: =J16/LbsPerHour*DelivLaborShare*Wage*(1+WageGrowth)^J$8*(1+Burden) -> 0 | K39: =K16/LbsPerHour*DelivLaborShare*Wage*(1+WageGrowth)^K$8*(1+Burden) -> 0 | ... T39: =T16/LbsPerHour*DelivLaborShare*Wage*(1+WageGrowth)^T$8*(1+Burden) -> 0 | U39: =SUM(D39:T39) -> 0
B40: Delivery program: supplies + utilities | D40: =D16*(WFSupplyLb+DelivUtilLb)*(1+ExpInfl)^D$8 -> 0 | E40: =E16*(WFSupplyLb+DelivUtilLb)*(1+ExpInfl)^E$8 -> 0 | F40: =F16*(WFSupplyLb+DelivUtilLb)*(1+ExpInfl)^F$8 -> 0 | G40: =G16*(WFSupplyLb+DelivUtilLb)*(1+ExpInfl)^G$8 -> 0 | H40: =H16*(WFSupplyLb+DelivUtilLb)*(1+ExpInfl)^H$8 -> 0 | I40: =I16*(WFSupplyLb+DelivUtilLb)*(1+ExpInfl)^I$8 -> 0 | J40: =J16*(WFSupplyLb+DelivUtilLb)*(1+ExpInfl)^J$8 -> 0 | K40: =K16*(WFSupplyLb+DelivUtilLb)*(1+ExpInfl)^K$8 -> 0 | ... T40: =T16*(WFSupplyLb+DelivUtilLb)*(1+ExpInfl)^T$8 -> 0 | U40: =SUM(D40:T40) -> 0
B41: Delivery program: driver + vehicle | D41: =IF(D16>0,DriverHours*52*DriverWage*(1+WageGrowth)^D$8*(1+Burden)+VehicleCost*(1+ExpInfl)^D$8,0) -> 0 | E41: =IF(E16>0,DriverHours*52*DriverWage*(1+WageGrowth)^E$8*(1+Burden)+VehicleCost*(1+ExpInfl)^E$8,0) -> 0 | F41: =IF(F16>0,DriverHours*52*DriverWage*(1+WageGrowth)^F$8*(1+Burden)+VehicleCost*(1+ExpInfl)^F$8,0) -> 0 | G41: =IF(G16>0,DriverHours*52*DriverWage*(1+WageGrowth)^G$8*(1+Burden)+VehicleCost*(1+ExpInfl)^G$8,0) -> 0 | H41: =IF(H16>0,DriverHours*52*DriverWage*(1+WageGrowth)^H$8*(1+Burden)+VehicleCost*(1+ExpInfl)^H$8,0) -> 0 | I41: =IF(I16>0,DriverHours*52*DriverWage*(1+WageGrowth)^I$8*(1+Burden)+VehicleCost*(1+ExpInfl)^I$8,0) -> 0 | J41: =IF(J16>0,DriverHours*52*DriverWage*(1+WageGrowth)^J$8*(1+Burden)+VehicleCost*(1+ExpInfl)^J$8,0) -> 0 | K41: =IF(K16>0,DriverHours*52*DriverWage*(1+WageGrowth)^K$8*(1+Burden)+VehicleCost*(1+ExpInfl)^K$8,0) -> 0 | ... T41: =IF(T16>0,DriverHours*52*DriverWage*(1+WageGrowth)^T$8*(1+Burden)+VehicleCost*(1+ExpInfl)^T$8,0) -> 0 | U41: =SUM(D41:T41) -> 0
B42: Contingency | D42: =D18*ContPct -> 3701.7 | E42: =E18*ContPct -> 3869.334 | F42: =F18*ContPct -> 3981.9287 | G42: =G18*ContPct -> 4097.8315 | H42: =H18*ContPct -> 4294.8317 | I42: =I18*ContPct -> 4419.978 | J42: =J18*ContPct -> 4548.8047 | K42: =K18*ContPct -> 4681.4207 | ... T42: =T18*ContPct -> 6127.6809 | U42: =SUM(D42:T42) -> 82728.79
B43: Total operating expenses | D43: =SUM(D21:D42) -> 262202.9 | E43: =SUM(E21:E42) -> 271544.01 | F43: =SUM(F21:F42) -> 281481.81 | G43: =SUM(G21:G42) -> 291814.75 | H43: =SUM(H21:H42) -> 287145.41 | I43: =SUM(I21:I42) -> 297227.3 | J43: =SUM(J21:J42) -> 307681.48 | K43: =SUM(K21:K42) -> 318522.8 | ... T43: =SUM(T21:T42) -> 416509.51 | U43: =SUM(D43:T43) -> 5643752.8
B45: EBITDA / net operating income (absentee) | D45: =D18-D43 -> 107967.1 | E45: =E18-E43 -> 115389.39 | F45: =F18-F43 -> 116711.05 | G45: =G18-G43 -> 117968.4 | H45: =H18-H43 -> 142337.76 | I45: =I18-I43 -> 144770.5 | J45: =J18-J43 -> 147198.99 | K45: =K18-K43 -> 149619.28 | ... T45: =T18-T43 -> 196258.57 | U45: =SUM(D45:T45) -> 2629126.2
...

Sheet Structures
B2: After-tax cash flow by ownership structure (family level)
B3: A: Ryan owns (parents gift the cash), works 40 hrs/wk unpaid. D: Ryan owns, funded by an AFR loan, S-corp from Year 2. B: parents' LLC owns, parents passive, no other passive income; Ryan paid W-2 for his hours. C: same as B but parents have passive income and NJ partnership income to absorb losses. Structure advice is in the ownership thread.
B5: Year | C5: 0 | D5: 1 | E5: 2 | F5: 3 | G5: 4 | H5: 5 | I5: 6 | J5: 7 | K5: 8 | L5: 9 | M5: 10 | N5: 11 | O5: 12 | P5: 13 | Q5: 14 | R5: 15 | S5: 16 | T5: 17 | U5: Total 1-17
B6: Common lines (from Projection and Depreciation)
B7: EBITDA (absentee) | D7: =Projection!D45 -> 107967.1 | E7: =Projection!E45 -> 115389.39 | F7: =Projection!F45 -> 116711.05 | G7: =Projection!G45 -> 117968.4 | H7: =Projection!H45 -> 142337.76 | I7: =Projection!I45 -> 144770.5 | J7: =Projection!J45 -> 147198.99 | K7: =Projection!K45 -> 149619.28 | ... T7: =Projection!T45 -> 196258.57 | U7: =SUM(D7:T7) -> 2629126.2
B8: Value of Ryan's hours | D8: =Projection!D48 -> 42224 | E8: =Projection!E48 -> 43701.84 | F8: =Projection!F48 -> 45231.404 | G8: =Projection!G48 -> 46814.504 | H8: =Projection!H48 -> 48453.011 | I8: =Projection!I48 -> 50148.867 | J8: =Projection!J48 -> 51904.077 | K8: =Projection!K48 -> 53720.72 | ... T8: =Projection!T48 -> 73215.827 | U8: =SUM(D8:T8) -> 958696.58
B9: W-2 wages paid (all attendant hours) | D9: =Projection!D22 -> 82810 | E9: =Projection!E22 -> 85708.35 | F9: =Projection!F22 -> 88708.142 | G9: =Projection!G22 -> 91812.927 | H9: =Projection!H22 -> 95026.38 | I9: =Projection!I22 -> 98352.303 | J9: =Projection!J22 -> 101794.63 | K9: =Projection!K22 -> 105357.45 | ... T9: =Projection!T22 -> 143591.38 | U9: =SUM(D9:T9) -> 1880202.4
B10: Federal depreciation & amortization | D10: =Depreciation!D69 -> 110666.67 | E10: =Depreciation!E69 -> 25666.667 | F10: =Depreciation!F69 -> 25666.667 | G10: =Depreciation!G69 -> 444918.7 | H10: =Depreciation!H69 -> 25666.667 | I10: =Depreciation!I69 -> 25666.667 | J10: =Depreciation!J69 -> 25666.667 | K10: =Depreciation!K69 -> 25666.667 | ... T10: =Depreciation!T69 -> 0 | U10: =SUM(D10:T10) -> 1125956
B11: NJ depreciation & amortization | D11: =Depreciation!D70 -> 58500 | E11: =Depreciation!E70 -> 38533.333 | F11: =Depreciation!F70 -> 34053.333 | G11: =Depreciation!G70 -> 135215.74 | H11: =Depreciation!H70 -> 157525.98 | I11: =Depreciation!I70 -> 105045.72 | J11: =Depreciation!J70 -> 72751.167 | K11: =Depreciation!K70 -> 72751.167 | ... T11: =Depreciation!T70 -> 0 | U11: =SUM(D11:T11) -> 1125956
B12: UBIA proxy | D12: =Depreciation!D71 -> 85000 | E12: =Depreciation!E71 -> 85000 | F12: =Depreciation!F71 -> 85000 | G12: =Depreciation!G71 -> 504252.03 | H12: =Depreciation!H71 -> 504252.03 | I12: =Depreciation!I71 -> 504252.03 | J12: =Depreciation!J71 -> 504252.03 | K12: =Depreciation!K71 -> 504252.03 | ... T12: =Depreciation!T71 -> 740956.02
B13: Pre-tax cash flow (absentee) | C13: =Projection!C55 -> -480000 | D13: =Projection!D55 -> 107967.1 | E13: =Projection!E55 -> 115389.39 | F13: =Projection!F55 -> 116711.05 | G13: =Projection!G55 -> -301283.63 | H13: =Projection!H55 -> 142337.76 | I13: =Projection!I55 -> 144770.5 | J13: =Projection!J55 -> 147198.99 | ... T13: =Projection!T55 -> 500646.43 | U13: =SUM(D13:T13) -> 2277558
B14: Exit value in cash flow | D14: =Projection!D54-IF(D$5=17,WorkingCap,0) -> 0 | E14: =Projection!E54-IF(E$5=17,WorkingCap,0) -> 0 | F14: =Projection!F54-IF(F$5=17,WorkingCap,0) -> 0 | G14: =Projection!G54-IF(G$5=17,WorkingCap,0) -> 0 | H14: =Projection!H54-IF(H$5=17,WorkingCap,0) -> 0 | I14: =Projection!I54-IF(I$5=17,WorkingCap,0) -> 0 | J14: =Projection!J54-IF(J$5=17,WorkingCap,0) -> 0 | K14: =Projection!K54-IF(K$5=17,WorkingCap,0) -> 0 | ... T14: =Projection!T54-IF(T$5=17,WorkingCap,0) -> 294387.86 | U14: =SUM(D14:T14) -> 294387.86
B16: A. Ryan owns 100% (single-member LLC, materially participates)
B17: Net business income (EBITDA + Ryan's unpaid hours - federal depreciation) | D17: =D7+D8-D10 -> 39524.433 | E17: =E7+E8-E10 -> 133424.56 | F17: =F7+F8-F10 -> 136275.79 | G17: =G7+G8-G10 -> -280135.79 | H17: =H7+H8-H10 -> 165124.1 | I17: =I7+I8-I10 -> 169252.7 | J17: =J7+J8-J10 -> 173436.4 | K17: =K7+K8-K10 -> 177673.33 | ... T17: =T7+T8-T10 -> 269474.4 | U17: =SUM(D17:T17) -> 2461866.7
B18: Self-employment tax | D18: =IF(D17>0,MIN(D17*0.9235,SSBase*(1+WageGrowth)^(D$5-1))*0.124+D17*0.9235*0.029,0) -> 5584.6246 | E18: =IF(E17>0,MIN(E17*0.9235,SSBase*(1+WageGrowth)^(E$5-1))*0.124+E17*0.9235*0.029,0) -> 18852.29 | F18: =IF(F17>0,MIN(F17*0.9235,SSBase*(1+WageGrowth)^(F$5-1))*0.124+F17*0.9235*0.029,0) -> 19255.156 | G18: =IF(G17>0,MIN(G17*0.9235,SSBase*(1+WageGrowth)^(G$5-1))*0.124+G17*0.9235*0.029,0) -> 0 | H18: =IF(H17>0,MIN(H17*0.9235,SSBase*(1+WageGrowth)^(H$5-1))*0.124+H17*0.9235*0.029,0) -> 23331.293 | I18: =IF(I17>0,MIN(I17*0.9235,SSBase*(1+WageGrowth)^(I$5-1))*0.124+I17*0.9235*0.029,0) -> 23914.645 | J18: =IF(J17>0,MIN(J17*0.9235,SSBase*(1+WageGrowth)^(J$5-1))*0.124+J17*0.9235*0.029,0) -> 24505.784 | K18: =IF(K17>0,MIN(K17*0.9235,SSBase*(1+WageGrowth)^(K$5-1))*0.124+K17*0.9235*0.029,0) -> 25104.442 | ... T18: =IF(T17>0,MIN(T17*0.9235,SSBase*(1+WageGrowth)^(T$5-1))*0.124+T17*0.9235*0.029,0) -> 38075.52 | U18: =SUM(D18:T18) -> 393935.53
B19: QBI deduction (below threshold: 20%) | D19: =MAX(0,D17-D18/2)*QBIRate -> 7346.4242 | E19: =MAX(0,E17-E18/2)*QBIRate -> 24799.684 | F19: =MAX(0,F17-F18/2)*QBIRate -> 25329.643 | G19: =MAX(0,G17-G18/2)*QBIRate -> 0 | H19: =MAX(0,H17-H18/2)*QBIRate -> 30691.691 | I19: =MAX(0,I17-I18/2)*QBIRate -> 31459.076 | J19: =MAX(0,J17-J18/2)*QBIRate -> 32236.703 | K19: =MAX(0,K17-K18/2)*QBIRate -> 33024.222 | ... T19: =MAX(0,T17-T18/2)*QBIRate -> 50087.327 | U19: =SUM(D19:T19) -> 518211.66
B20: Federal taxable income from the business | D20: =D17-D18/2-D19 -> 29385.697 | E20: =E17-E18/2-E19 -> 99198.735 | F20: =F17-F18/2-F19 -> 101318.57 | G20: =G17-G18/2-G19 -> -280135.79 | H20: =H17-H18/2-H19 -> 122766.77 | I20: =I17-I18/2-I19 -> 125836.3 | J20: =J17-J18/2-J19 -> 128946.81 | K20: =K17-K18/2-K19 -> 132096.89 | ... T20: =T17-T18/2-T19 -> 200349.31 | U20: =SUM(D20:T20) -> 1746687.3
B21: Fed loss carryforward, start of year | D21: =0 -> 0 | E21: =D24 -> 0 | F21: =E24 -> 0 | G21: =F24 -> 0 | H21: =G24 -> 230135.79 | I21: =H24 -> 107369.03 | J21: =I24 -> 0 | K21: =J24 -> 0 | L21: =K24 -> 0 | ... T21: =S24 -> 0
B22: Fed carryforward used | D22: =MIN(D21,MAX(0,D20)) -> 0 | E22: =MIN(E21,MAX(0,E20)) -> 0 | F22: =MIN(F21,MAX(0,F20)) -> 0 | G22: =MIN(G21,MAX(0,G20)) -> 0 | H22: =MIN(H21,MAX(0,H20)) -> 122766.77 | I22: =MIN(I21,MAX(0,I20)) -> 107369.03 | J22: =MIN(J21,MAX(0,J20)) -> 0 | K22: =MIN(K21,MAX(0,K20)) -> 0 | ... T22: =MIN(T21,MAX(0,T20)) -> 0 | U22: =SUM(D22:T22) -> 230135.79
B23: Fed loss used against other income | D23: =IF(D20<0,MIN(-D20,MIN(RyanOtherInc,EBLSingle)),0) -> 0 | E23: =IF(E20<0,MIN(-E20,MIN(RyanOtherInc,EBLSingle)),0) -> 0 | F23: =IF(F20<0,MIN(-F20,MIN(RyanOtherInc,EBLSingle)),0) -> 0 | G23: =IF(G20<0,MIN(-G20,MIN(RyanOtherInc,EBLSingle)),0) -> 50000 | H23: =IF(H20<0,MIN(-H20,MIN(RyanOtherInc,EBLSingle)),0) -> 0 | I23: =IF(I20<0,MIN(-I20,MIN(RyanOtherInc,EBLSingle)),0) -> 0 | J23: =IF(J20<0,MIN(-J20,MIN(RyanOtherInc,EBLSingle)),0) -> 0 | K23: =IF(K20<0,MIN(-K20,MIN(RyanOtherInc,EBLSingle)),0) -> 0 | ... T23: =IF(T20<0,MIN(-T20,MIN(RyanOtherInc,EBLSingle)),0) -> 0 | U23: =SUM(D23:T23) -> 96023.521
B24: Fed loss carryforward, end of year | D24: =D21-D22+MAX(0,-D20)-D23 -> 0 | E24: =E21-E22+MAX(0,-E20)-E23 -> 0 | F24: =F21-F22+MAX(0,-F20)-F23 -> 0 | G24: =G21-G22+MAX(0,-G20)-G23 -> 230135.79 | H24: =H21-H22+MAX(0,-H20)-H23 -> 107369.03 | I24: =I21-I22+MAX(0,-I20)-I23 -> 0 | J24: =J21-J22+MAX(0,-J20)-J23 -> 0 | K24: =K21-K22+MAX(0,-K20)-K23 -> 0 | ... T24: =T21-T22+MAX(0,-T20)-T23 -> 0
B25: Fed tax (negative = tax saved on other income) | D25: =(MAX(0,D20)-D22-D23)*RyanFed -> 6464.8533 | E25: =(MAX(0,E20)-E22-E23)*RyanFed -> 21823.722 | F25: =(MAX(0,F20)-F22-F23)*RyanFed -> 22290.086 | G25: =(MAX(0,G20)-G22-G23)*RyanFed -> -11000 | H25: =(MAX(0,H20)-H22-H23)*RyanFed -> 0 | I25: =(MAX(0,I20)-I22-I23)*RyanFed -> 4062.8012 | J25: =(MAX(0,J20)-J22-J23)*RyanFed -> 28368.298 | K25: =(MAX(0,K20)-K22-K23)*RyanFed -> 29061.315 | ... T25: =(MAX(0,T20)-T22-T23)*RyanFed -> 44076.848 | U25: =SUM(D25:T25) -> 384271.21
B26: NJ taxable income (EBITDA + Ryan's hours - NJ depreciation) | D26: =D7+D8-D11 -> 91691.1 | E26: =E7+E8-E11 -> 120557.9 | F26: =F7+F8-F11 -> 127889.12 | G26: =G7+G8-G11 -> 29567.168 | H26: =H7+H8-H11 -> 33264.786 | I26: =I7+I8-I11 -> 89873.645 | J26: =J7+J8-J11 -> 126351.9 | K26: =K7+K8-K11 -> 130588.83 | ... T26: =T7+T8-T11 -> 269474.4 | U26: =SUM(D26:T26) -> 2461866.7
B27: NJ loss carryforward, start of year | D27: =0 -> 0 | E27: =D30 -> 0 | F27: =E30 -> 0 | G27: =F30 -> 0 | H27: =G30 -> 0 | I27: =H30 -> 0 | J27: =I30 -> 0 | K27: =J30 -> 0 | L27: =K30 -> 0 | ... T27: =S30 -> 0
B28: NJ carryforward used | D28: =MIN(D27,MAX(0,D26)) -> 0 | E28: =MIN(E27,MAX(0,E26)) -> 0 | F28: =MIN(F27,MAX(0,F26)) -> 0 | G28: =MIN(G27,MAX(0,G26)) -> 0 | H28: =MIN(H27,MAX(0,H26)) -> 0 | I28: =MIN(I27,MAX(0,I26)) -> 0 | J28: =MIN(J27,MAX(0,J26)) -> 0 | K28: =MIN(K27,MAX(0,K26)) -> 0 | ... T28: =MIN(T27,MAX(0,T26)) -> 0 | U28: =SUM(D28:T28) -> 0
B29: NJ loss used against other income | D29: =IF(D26<0,MIN(-D26,0),0) -> 0 | E29: =IF(E26<0,MIN(-E26,0),0) -> 0 | F29: =IF(F26<0,MIN(-F26,0),0) -> 0 | G29: =IF(G26<0,MIN(-G26,0),0) -> 0 | H29: =IF(H26<0,MIN(-H26,0),0) -> 0 | I29: =IF(I26<0,MIN(-I26,0),0) -> 0 | J29: =IF(J26<0,MIN(-J26,0),0) -> 0 | K29: =IF(K26<0,MIN(-K26,0),0) -> 0 | ... T29: =IF(T26<0,MIN(-T26,0),0) -> 0 | U29: =SUM(D29:T29) -> 0
B30: NJ loss carryforward, end of year | D30: =D27-D28+MAX(0,-D26)-D29 -> 0 | E30: =E27-E28+MAX(0,-E26)-E29 -> 0 | F30: =F27-F28+MAX(0,-F26)-F29 -> 0 | G30: =G27-G28+MAX(0,-G26)-G29 -> 0 | H30: =H27-H28+MAX(0,-H26)-H29 -> 0 | I30: =I27-I28+MAX(0,-I26)-I29 -> 0 | J30: =J27-J28+MAX(0,-J26)-J29 -> 0 | K30: =K27-K28+MAX(0,-K26)-K29 -> 0 | ... T30: =T27-T28+MAX(0,-T26)-T29 -> 0
B31: NJ tax (negative = tax saved on other income) | D31: =(MAX(0,D26)-D28-D29)*RyanNJ -> 5840.7231 | E31: =(MAX(0,E26)-E28-E29)*RyanNJ -> 7679.538 | F31: =(MAX(0,F26)-F28-F29)*RyanNJ -> 8146.5373 | G31: =(MAX(0,G26)-G28-G29)*RyanNJ -> 1883.4286 | H31: =(MAX(0,H26)-H28-H29)*RyanNJ -> 2118.9669 | I31: =(MAX(0,I26)-I28-I29)*RyanNJ -> 5724.9512 | J31: =(MAX(0,J26)-J28-J29)*RyanNJ -> 8048.6163 | K31: =(MAX(0,K26)-K28-K29)*RyanNJ -> 8318.5084 | ... T31: =(MAX(0,T26)-T28-T29)*RyanNJ -> 17165.519 | U31: =SUM(D31:T31) -> 156820.91
B32: Total tax (federal + SE + NJ) | D32: =D25+D18+D31 -> 17890.201 | E32: =E25+E18+E31 -> 48355.55 | F32: =F25+F18+F31 -> 49691.779 | G32: =G25+G18+G31 -> -9116.5714 | H32: =H25+H18+H31 -> 25450.259 | I32: =I25+I18+I31 -> 33702.398 | J32: =J25+J18+J31 -> 60922.698 | K32: =K25+K18+K31 -> 62484.266 | ... T32: =T25+T18+T31 -> 99317.887 | U32: =SUM(D32:T32) -> 935027.66
B33: Family after-tax cash flow | C33: =C13 -> -480000 | D33: =D13+D8-D32-D14*ExitTax -> 132300.9 | E33: =E13+E8-E32-E14*ExitTax -> 110735.68 | F33: =F13+F8-F32-F14*ExitTax -> 112250.68 | G33: =G13+G8-G32-G14*ExitTax -> -245352.55 | H33: =H13+H8-H32-H14*ExitTax -> 165340.51 | I33: =I13+I8-I32-I14*ExitTax -> 161216.97 | J33: =J13+J8-J32-J14*ExitTax -> 138180.37 | K33: =K13+K8-K32-K14*ExitTax -> 140855.73 | ... T33: =T13+T8-T32-T14*ExitTax -> 386228.01 | U33: =SUM(D33:T33) -> 2212910.6
B35: B. Parents' LLC owns 100%; parents passive with no other passive income; Ryan is a paid W-2 manager
B36: Net business income (EBITDA - federal depreciation) | D36: =D7-D10 -> -2699.5667 | E36: =E7-E10 -> 89722.723 | F36: =F7-F10 -> 91044.387 | G36: =G7-G10 -> -326950.29 | H36: =H7-H10 -> 116671.09 | I36: =I7-I10 -> 119103.84 | J36: =J7-J10 -> 121532.33 | K36: =K7-K10 -> 123952.61 | ... T36: =T7-T10 -> 196258.57 | U36: =SUM(D36:T36) -> 1503170.2
B37: QBI deduction (above threshold: limited by W-2 wages / property) | D37: =MIN(MAX(0,D36)*QBIRate,MAX(0.5*D9,0.25*D9+0.025*D12)) -> 0 | E37: =MIN(MAX(0,E36)*QBIRate,MAX(0.5*E9,0.25*E9+0.025*E12)) -> 17944.545 | F37: =MIN(MAX(0,F36)*QBIRate,MAX(0.5*F9,0.25*F9+0.025*F12)) -> 18208.877 | G37: =MIN(MAX(0,G36)*QBIRate,MAX(0.5*G9,0.25*G9+0.025*G12)) -> 0 | H37: =MIN(MAX(0,H36)*QBIRate,MAX(0.5*H9,0.25*H9+0.025*H12)) -> 23334.218 | I37: =MIN(MAX(0,I36)*QBIRate,MAX(0.5*I9,0.25*I9+0.025*I12)) -> 23820.767 | J37: =MIN(MAX(0,J36)*QBIRate,MAX(0.5*J9,0.25*J9+0.025*J12)) -> 24306.466 | K37: =MIN(MAX(0,K36)*QBIRate,MAX(0.5*K9,0.25*K9+0.025*K12)) -> 24790.522 | ... T37: =MIN(MAX(0,T36)*QBIRate,MAX(0.5*T9,0.25*T9+0.025*T12)) -> 39251.714 | U37: =SUM(D37:T37) -> 387680.93
B38: Federal taxable income from the business | D38: =D36-D37 -> -2699.5667 | E38: =E36-E37 -> 71778.179 | F38: =F36-F37 -> 72835.51 | G38: =G36-G37 -> -326950.29 | H38: =H36-H37 -> 93336.873 | I38: =I36-I37 -> 95283.069 | J38: =J36-J37 -> 97225.862 | K38: =K36-K37 -> 99162.088 | ... T38: =T36-T37 -> 157006.86 | U38: =SUM(D38:T38) -> 1115489.2
B39: Fed (passive) loss carryforward, start of year | D39: =0 -> 0 | E39: =D42 -> 2699.5667 | F39: =E42 -> 0 | G39: =F42 -> 0 | H39: =G42 -> 326950.29 | I39: =H42 -> 233613.42 | J39: =I42 -> 138330.35 | K39: =J42 -> 41104.49 | L39: =K42 -> 0 | ... T39: =S42 -> 0
B40: Fed (passive) carryforward used | D40: =MIN(D39,MAX(0,D38)) -> 0 | E40: =MIN(E39,MAX(0,E38)) -> 2699.5667 | F40: =MIN(F39,MAX(0,F38)) -> 0 | G40: =MIN(G39,MAX(0,G38)) -> 0 | H40: =MIN(H39,MAX(0,H38)) -> 93336.873 | I40: =MIN(I39,MAX(0,I38)) -> 95283.069 | J40: =MIN(J39,MAX(0,J38)) -> 97225.862 | K40: =MIN(K39,MAX(0,K38)) -> 41104.49 | ... T40: =MIN(T39,MAX(0,T38)) -> 0 | U40: =SUM(D40:T40) -> 435234.5
B41: Fed (passive) loss used against other income | D41: =IF(D38<0,MIN(-D38,0),0) -> 0 | E41: =IF(E38<0,MIN(-E38,0),0) -> 0 | F41: =IF(F38<0,MIN(-F38,0),0) -> 0 | G41: =IF(G38<0,MIN(-G38,0),0) -> 0 | H41: =IF(H38<0,MIN(-H38,0),0) -> 0 | I41: =IF(I38<0,MIN(-I38,0),0) -> 0 | J41: =IF(J38<0,MIN(-J38,0),0) -> 0 | K41: =IF(K38<0,MIN(-K38,0),0) -> 0 | ... T41: =IF(T38<0,MIN(-T38,0),0) -> 0 | U41: =SUM(D41:T41) -> 0
B42: Fed (passive) loss carryforward, end of year | D42: =D39-D40+MAX(0,-D38)-D41 -> 2699.5667 | E42: =E39-E40+MAX(0,-E38)-E41 -> 0 | F42: =F39-F40+MAX(0,-F38)-F41 -> 0 | G42: =G39-G40+MAX(0,-G38)-G41 -> 326950.29 | H42: =H39-H40+MAX(0,-H38)-H41 -> 233613.42 | I42: =I39-I40+MAX(0,-I38)-I41 -> 138330.35 | J42: =J39-J40+MAX(0,-J38)-J41 -> 41104.49 | K42: =K39-K40+MAX(0,-K38)-K41 -> 0 | ... T42: =T39-T40+MAX(0,-T38)-T41 -> 0
B43: Fed (passive) tax (negative = tax saved on other income) | D43: =(MAX(0,D38)-D40-D41)*(ParentFed+NIIT) -> 0 | E43: =(MAX(0,E38)-E40-E41)*(ParentFed+NIIT) -> 28184.074 | F43: =(MAX(0,F38)-F40-F41)*(ParentFed+NIIT) -> 29716.888 | G43: =(MAX(0,G38)-G40-G41)*(ParentFed+NIIT) -> 0 | H43: =(MAX(0,H38)-H40-H41)*(ParentFed+NIIT) -> 0 | I43: =(MAX(0,I38)-I40-I41)*(ParentFed+NIIT) -> 0 | J43: =(MAX(0,J38)-J40-J41)*(ParentFed+NIIT) -> 0 | K43: =(MAX(0,K38)-K40-K41)*(ParentFed+NIIT) -> 23687.5 | ... T43: =(MAX(0,T38)-T40-T41)*(ParentFed+NIIT) -> 64058.797 | U43: =SUM(D43:T43) -> 455119.6
B44: NJ taxable income (EBITDA - NJ depreciation) | D44: =D7-D11 -> 49467.1 | E44: =E7-E11 -> 76856.057 | F44: =F7-F11 -> 82657.72 | G44: =G7-G11 -> -17247.335 | H44: =H7-H11 -> -15188.225 | I44: =I7-I11 -> 39724.779 | J44: =J7-J11 -> 74447.827 | K44: =K7-K11 -> 76868.11 | ... T44: =T7-T11 -> 196258.57 | U44: =SUM(D44:T44) -> 1503170.2
...

Sheet Depreciation
B2: Capex plan and depreciation (federal vs. state)
B3: Columns are years 0 (closing) to 17. Year-0 spend is placed in service in tax Year 1.
B5: Year | C5: 0 | D5: 1 | E5: 2 | F5: 3 | G5: 4 | H5: 5 | I5: 6 | J5: 7 | K5: 8 | L5: 9 | M5: 10 | N5: 11 | O5: 12 | P5: 13 | Q5: 14 | R5: 15 | S5: 16 | T5: 17
B7: Capex schedule by scenario (today's $; source: equipment thread capex_schedule.csv)
B8: 1 Keep & repair; replace as machines wear out (yr 4, yr 11) | C8: 0 | D8: 0 | E8: 0 | F8: 0 | G8: 372500 | H8: 0 | I8: 0 | J8: 0 | K8: 0 | L8: 0 | M8: 0 | N8: 171000 | O8: 0 | P8: 0 | Q8: 0 | R8: 0 | S8: 0 | T8: 0 | U8: Source: capex_scenarios.json (2026-10-16)
B9: 2 Washers at close; dryers as they wear out (yr 0, yr 11) | C9: 363188 | D9: 0 | E9: 0 | F9: 0 | G9: 0 | H9: 0 | I9: 0 | J9: 0 | K9: 0 | L9: 0 | M9: 0 | N9: 171000 | O9: 0 | P9: 0 | Q9: 0 | R9: 0 | S9: 0 | T9: 0
B10: 3 Full retool at close (yr 0) | C10: 529912 | D10: 0 | E10: 0 | F10: 0 | G10: 0 | H10: 0 | I10: 0 | J10: 0 | K10: 0 | L10: 0 | M10: 0 | N10: 0 | O10: 0 | P10: 0 | Q10: 0 | R10: 0 | S10: 0 | T10: 0
B11: 4 Bear: fleet 3 yrs older than stated (yr 1, yr 8) | C11: 0 | D11: 372500 | E11: 0 | F11: 0 | G11: 0 | H11: 0 | I11: 0 | J11: 0 | K11: 171000 | L11: 0 | M11: 0 | N11: 0 | O11: 0 | P11: 0 | Q11: 0 | R11: 0 | S11: 0 | T11: 0
B12: Selected scenario capex (inflated) | C12: =INDEX(C8:C11,CapexScenario)*(1+CapexInfl)^C$5 -> 0 | D12: =INDEX(D8:D11,CapexScenario)*(1+CapexInfl)^D$5 -> 0 | E12: =INDEX(E8:E11,CapexScenario)*(1+CapexInfl)^E$5 -> 0 | F12: =INDEX(F8:F11,CapexScenario)*(1+CapexInfl)^F$5 -> 0 | G12: =INDEX(G8:G11,CapexScenario)*(1+CapexInfl)^G$5 -> 419252.03 | H12: =INDEX(H8:H11,CapexScenario)*(1+CapexInfl)^H$5 -> 0 | I12: =INDEX(I8:I11,CapexScenario)*(1+CapexInfl)^I$5 -> 0 | J12: =INDEX(J8:J11,CapexScenario)*(1+CapexInfl)^J$5 -> 0 | ... T12: =INDEX(T8:T11,CapexScenario)*(1+CapexInfl)^T$5 -> 0
B13: Share of fleet that is new (drives revenue lift, utilities, repairs) | C13: =0 -> 0 | D13: =IF(SUM($C$12:$T$12)=0,0,SUM($C$12:C$12)/SUM($C$12:$T$12)) -> 0 | E13: =IF(SUM($C$12:$T$12)=0,0,SUM($C$12:D$12)/SUM($C$12:$T$12)) -> 0 | F13: =IF(SUM($C$12:$T$12)=0,0,SUM($C$12:E$12)/SUM($C$12:$T$12)) -> 0 | G13: =IF(SUM($C$12:$T$12)=0,0,SUM($C$12:F$12)/SUM($C$12:$T$12)) -> 0 | H13: =IF(SUM($C$12:$T$12)=0,0,SUM($C$12:G$12)/SUM($C$12:$T$12)) -> 0.63914655 | I13: =IF(SUM($C$12:$T$12)=0,0,SUM($C$12:H$12)/SUM($C$12:$T$12)) -> 0.63914655 | J13: =IF(SUM($C$12:$T$12)=0,0,SUM($C$12:I$12)/SUM($C$12:$T$12)) -> 0.63914655 | K13: =IF(SUM($C$12:$T$12)=0,0,SUM($C$12:J$12)/SUM($C$12:$T$12)) -> 0.63914655 | ... T13: =IF(SUM($C$12:$T$12)=0,0,SUM($C$12:S$12)/SUM($C$12:$T$12)) -> 1
B15: MACRS rate tables (half-year convention), by recovery year 1-20
B16: 5-yr MACRS 200DB | C16: 0.2 | D16: 0.32 | E16: 0.192 | F16: 0.1152 | G16: 0.1152 | H16: 0.0576 | I16: 0 | J16: 0 | K16: 0 | L16: 0 | M16: 0 | N16: 0 | O16: 0 | P16: 0 | Q16: 0 | R16: 0 | S16: 0 | T16: 0 | U16: 0 | V16: 0 | X16: IRS Pub 946 Table A-1
B17: 7-yr MACRS 200DB | C17: 0.1429 | D17: 0.2449 | E17: 0.1749 | F17: 0.1249 | G17: 0.0893 | H17: 0.0892 | I17: 0.0893 | J17: 0.0446 | K17: 0 | L17: 0 | M17: 0 | N17: 0 | O17: 0 | P17: 0 | Q17: 0 | R17: 0 | S17: 0 | T17: 0 | U17: 0 | V17: 0
B18: 15-yr straight line (QIP) | C18: 0.033333333 | D18: 0.066666667 | E18: 0.066666667 | F18: 0.066666667 | G18: 0.066666667 | H18: 0.066666667 | I18: 0.066666667 | J18: 0.066666667 | K18: 0.066666667 | L18: 0.066666667 | M18: 0.066666667 | N18: 0.066666667 | O18: 0.066666667 | P18: 0.066666667 | Q18: 0.066666667 | R18: 0.033333333 | S18: 0 | T18: 0 | U18: 0 | V18: 0
B19: Machines: selected table | C19: =IF(EquipLife=7,C17,C16) -> 0.2 | D19: =IF(EquipLife=7,D17,D16) -> 0.32 | E19: =IF(EquipLife=7,E17,E16) -> 0.192 | F19: =IF(EquipLife=7,F17,F16) -> 0.1152 | G19: =IF(EquipLife=7,G17,G16) -> 0.1152 | H19: =IF(EquipLife=7,H17,H16) -> 0.0576 | I19: =IF(EquipLife=7,I17,I16) -> 0 | J19: =IF(EquipLife=7,J17,J16) -> 0 | ... V19: =IF(EquipLife=7,V17,V16) -> 0
B21: Machines placed in service by tax year
B22: Machines placed in service (acquired fleet + capex) | D22: =AllocEquip+C12+D12 -> 60000 | E22: =E12 -> 0 | F22: =F12 -> 0 | G22: =G12 -> 419252.03 | H22: =H12 -> 0 | I22: =I12 -> 0 | J22: =J12 -> 0 | K22: =K12 -> 0 | L22: =L12 -> 0 | ... T22: =T12 -> 0
B24: Federal: machines (bonus + MACRS)
B25: Vintage year 1 | D25: =$D$22*(IF(1=1,Bonus,0)+(1-Bonus)*INDEX($C$19:$V$19,1)) -> 60000 | E25: =$D$22*(IF(2=1,Bonus,0)+(1-Bonus)*INDEX($C$19:$V$19,2)) -> 0 | F25: =$D$22*(IF(3=1,Bonus,0)+(1-Bonus)*INDEX($C$19:$V$19,3)) -> 0 | G25: =$D$22*(IF(4=1,Bonus,0)+(1-Bonus)*INDEX($C$19:$V$19,4)) -> 0 | H25: =$D$22*(IF(5=1,Bonus,0)+(1-Bonus)*INDEX($C$19:$V$19,5)) -> 0 | I25: =$D$22*(IF(6=1,Bonus,0)+(1-Bonus)*INDEX($C$19:$V$19,6)) -> 0 | J25: =$D$22*(IF(7=1,Bonus,0)+(1-Bonus)*INDEX($C$19:$V$19,7)) -> 0 | K25: =$D$22*(IF(8=1,Bonus,0)+(1-Bonus)*INDEX($C$19:$V$19,8)) -> 0 | L25: =$D$22*(IF(9=1,Bonus,0)+(1-Bonus)*INDEX($C$19:$V$19,9)) -> 0 | M25: =$D$22*(IF(10=1,Bonus,0)+(1-Bonus)*INDEX($C$19:$V$19,10)) -> 0 | N25: =$D$22*(IF(11=1,Bonus,0)+(1-Bonus)*INDEX($C$19:$V$19,11)) -> 0 | O25: =$D$22*(IF(12=1,Bonus,0)+(1-Bonus)*INDEX($C$19:$V$19,12)) -> 0 | P25: =$D$22*(IF(13=1,Bonus,0)+(1-Bonus)*INDEX($C$19:$V$19,13)) -> 0 | Q25: =$D$22*(IF(14=1,Bonus,0)+(1-Bonus)*INDEX($C$19:$V$19,14)) -> 0 | R25: =$D$22*(IF(15=1,Bonus,0)+(1-Bonus)*INDEX($C$19:$V$19,15)) -> 0 | S25: =$D$22*(IF(16=1,Bonus,0)+(1-Bonus)*INDEX($C$19:$V$19,16)) -> 0 | T25: =$D$22*(IF(17=1,Bonus,0)+(1-Bonus)*INDEX($C$19:$V$19,17)) -> 0
B26: Vintage year 2 | D26: =0 -> 0 | E26: =$E$22*(IF(2=2,Bonus,0)+(1-Bonus)*INDEX($C$19:$V$19,1)) -> 0 | F26: =$E$22*(IF(3=2,Bonus,0)+(1-Bonus)*INDEX($C$19:$V$19,2)) -> 0 | G26: =$E$22*(IF(4=2,Bonus,0)+(1-Bonus)*INDEX($C$19:$V$19,3)) -> 0 | H26: =$E$22*(IF(5=2,Bonus,0)+(1-Bonus)*INDEX($C$19:$V$19,4)) -> 0 | I26: =$E$22*(IF(6=2,Bonus,0)+(1-Bonus)*INDEX($C$19:$V$19,5)) -> 0 | J26: =$E$22*(IF(7=2,Bonus,0)+(1-Bonus)*INDEX($C$19:$V$19,6)) -> 0 | K26: =$E$22*(IF(8=2,Bonus,0)+(1-Bonus)*INDEX($C$19:$V$19,7)) -> 0 | L26: =$E$22*(IF(9=2,Bonus,0)+(1-Bonus)*INDEX($C$19:$V$19,8)) -> 0 | M26: =$E$22*(IF(10=2,Bonus,0)+(1-Bonus)*INDEX($C$19:$V$19,9)) -> 0 | N26: =$E$22*(IF(11=2,Bonus,0)+(1-Bonus)*INDEX($C$19:$V$19,10)) -> 0 | O26: =$E$22*(IF(12=2,Bonus,0)+(1-Bonus)*INDEX($C$19:$V$19,11)) -> 0 | P26: =$E$22*(IF(13=2,Bonus,0)+(1-Bonus)*INDEX($C$19:$V$19,12)) -> 0 | Q26: =$E$22*(IF(14=2,Bonus,0)+(1-Bonus)*INDEX($C$19:$V$19,13)) -> 0 | R26: =$E$22*(IF(15=2,Bonus,0)+(1-Bonus)*INDEX($C$19:$V$19,14)) -> 0 | S26: =$E$22*(IF(16=2,Bonus,0)+(1-Bonus)*INDEX($C$19:$V$19,15)) -> 0 | T26: =$E$22*(IF(17=2,Bonus,0)+(1-Bonus)*INDEX($C$19:$V$19,16)) -> 0
B27: Vintage year 3 | D27: =0 -> 0 | E27: =0 -> 0 | F27: =$F$22*(IF(3=3,Bonus,0)+(1-Bonus)*INDEX($C$19:$V$19,1)) -> 0 | G27: =$F$22*(IF(4=3,Bonus,0)+(1-Bonus)*INDEX($C$19:$V$19,2)) -> 0 | H27: =$F$22*(IF(5=3,Bonus,0)+(1-Bonus)*INDEX($C$19:$V$19,3)) -> 0 | I27: =$F$22*(IF(6=3,Bonus,0)+(1-Bonus)*INDEX($C$19:$V$19,4)) -> 0 | J27: =$F$22*(IF(7=3,Bonus,0)+(1-Bonus)*INDEX($C$19:$V$19,5)) -> 0 | K27: =$F$22*(IF(8=3,Bonus,0)+(1-Bonus)*INDEX($C$19:$V$19,6)) -> 0 | L27: =$F$22*(IF(9=3,Bonus,0)+(1-Bonus)*INDEX($C$19:$V$19,7)) -> 0 | M27: =$F$22*(IF(10=3,Bonus,0)+(1-Bonus)*INDEX($C$19:$V$19,8)) -> 0 | N27: =$F$22*(IF(11=3,Bonus,0)+(1-Bonus)*INDEX($C$19:$V$19,9)) -> 0 | O27: =$F$22*(IF(12=3,Bonus,0)+(1-Bonus)*INDEX($C$19:$V$19,10)) -> 0 | P27: =$F$22*(IF(13=3,Bonus,0)+(1-Bonus)*INDEX($C$19:$V$19,11)) -> 0 | Q27: =$F$22*(IF(14=3,Bonus,0)+(1-Bonus)*INDEX($C$19:$V$19,12)) -> 0 | R27: =$F$22*(IF(15=3,Bonus,0)+(1-Bonus)*INDEX($C$19:$V$19,13)) -> 0 | S27: =$F$22*(IF(16=3,Bonus,0)+(1-Bonus)*INDEX($C$19:$V$19,14)) -> 0 | T27: =$F$22*(IF(17=3,Bonus,0)+(1-Bonus)*INDEX($C$19:$V$19,15)) -> 0
